TelegramBot 03-10 INFO: started TelegramBot
TelegramBot 03-10 INFO: started TelegramBot
TelegramBot 03-10 INFO: Application started
TelegramBot 03-10 ERROR: No error handlers are registered, logging exception.
Traceback (most recent call last):
  File "/home/andres/coding/listapp2/venv/lib/python3.10/site-packages/telegram/ext/_application.py", line 1104, in process_update
    await coroutine
  File "/home/andres/coding/listapp2/venv/lib/python3.10/site-packages/telegram/ext/_handler.py", line 141, in handle_update
    return await self.callback(update, context)
  File "/home/andres/coding/listapp2/TelegramBot/tlbot.py", line 48, in echo
    text= bot_res
UnboundLocalError: local variable 'bot_res' referenced before assignment
TelegramBot 03-10 ERROR: No error handlers are registered, logging exception.
Traceback (most recent call last):
  File "/home/andres/coding/listapp2/venv/lib/python3.10/site-packages/anyio/streams/tls.py", line 130, in _call_sslobject_method
    result = func(*args)
  File "/usr/lib/python3.10/ssl.py", line 917, in read
    v = self._sslobj.read(len)
ssl.SSLWantReadError: The operation did not complete (read) (_ssl.c:2548)

During handling of the above exception, another exception occurred:

Traceback (most recent call last):
  File "/home/andres/coding/listapp2/venv/lib/python3.10/site-packages/httpcore/backends/asyncio.py", line 34, in read
    return await self._stream.receive(max_bytes=max_bytes)
  File "/home/andres/coding/listapp2/venv/lib/python3.10/site-packages/anyio/streams/tls.py", line 195, in receive
    data = await self._call_sslobject_method(self._ssl_object.read, max_bytes)
  File "/home/andres/coding/listapp2/venv/lib/python3.10/site-packages/anyio/streams/tls.py", line 137, in _call_sslobject_method
    data = await self.transport_stream.receive()
  File "/home/andres/coding/listapp2/venv/lib/python3.10/site-packages/anyio/_backends/_asyncio.py", line 1265, in receive
    await self._protocol.read_event.wait()
  File "/usr/lib/python3.10/asyncio/locks.py", line 214, in wait
    await fut
asyncio.exceptions.CancelledError

During handling of the above exception, another exception occurred:

Traceback (most recent call last):
  File "/home/andres/coding/listapp2/venv/lib/python3.10/site-packages/httpcore/_exceptions.py", line 10, in map_exceptions
    yield
  File "/home/andres/coding/listapp2/venv/lib/python3.10/site-packages/httpcore/backends/asyncio.py", line 32, in read
    with anyio.fail_after(timeout):
  File "/home/andres/coding/listapp2/venv/lib/python3.10/site-packages/anyio/_core/_tasks.py", line 118, in __exit__
    raise TimeoutError
TimeoutError

During handling of the above exception, another exception occurred:

Traceback (most recent call last):
  File "/home/andres/coding/listapp2/venv/lib/python3.10/site-packages/httpx/_transports/default.py", line 60, in map_httpcore_exceptions
    yield
  File "/home/andres/coding/listapp2/venv/lib/python3.10/site-packages/httpx/_transports/default.py", line 353, in handle_async_request
    resp = await self._pool.handle_async_request(req)
  File "/home/andres/coding/listapp2/venv/lib/python3.10/site-packages/httpcore/_async/connection_pool.py", line 253, in handle_async_request
    raise exc
  File "/home/andres/coding/listapp2/venv/lib/python3.10/site-packages/httpcore/_async/connection_pool.py", line 237, in handle_async_request
    response = await connection.handle_async_request(request)
  File "/home/andres/coding/listapp2/venv/lib/python3.10/site-packages/httpcore/_async/connection.py", line 90, in handle_async_request
    return await self._connection.handle_async_request(request)
  File "/home/andres/coding/listapp2/venv/lib/python3.10/site-packages/httpcore/_async/http2.py", line 144, in handle_async_request
    raise exc
  File "/home/andres/coding/listapp2/venv/lib/python3.10/site-packages/httpcore/_async/http2.py", line 112, in handle_async_request
    status, headers = await self._receive_response(
  File "/home/andres/coding/listapp2/venv/lib/python3.10/site-packages/httpcore/_async/http2.py", line 229, in _receive_response
    event = await self._receive_stream_event(request, stream_id)
  File "/home/andres/coding/listapp2/venv/lib/python3.10/site-packages/httpcore/_async/http2.py", line 260, in _receive_stream_event
    await self._receive_events(request, stream_id)
  File "/home/andres/coding/listapp2/venv/lib/python3.10/site-packages/httpcore/_async/http2.py", line 281, in _receive_events
    events = await self._read_incoming_data(request)
  File "/home/andres/coding/listapp2/venv/lib/python3.10/site-packages/httpcore/_async/http2.py", line 341, in _read_incoming_data
    raise exc
  File "/home/andres/coding/listapp2/venv/lib/python3.10/site-packages/httpcore/_async/http2.py", line 327, in _read_incoming_data
    data = await self._network_stream.read(self.READ_NUM_BYTES, timeout)
  File "/home/andres/coding/listapp2/venv/lib/python3.10/site-packages/httpcore/backends/asyncio.py", line 31, in read
    with map_exceptions(exc_map):
  File "/usr/lib/python3.10/contextlib.py", line 153, in __exit__
    self.gen.throw(typ, value, traceback)
  File "/home/andres/coding/listapp2/venv/lib/python3.10/site-packages/httpcore/_exceptions.py", line 14, in map_exceptions
    raise to_exc(exc)
httpcore.ReadTimeout

The above exception was the direct cause of the following exception:

Traceback (most recent call last):
  File "/home/andres/coding/listapp2/venv/lib/python3.10/site-packages/telegram/request/_httpxrequest.py", line 199, in do_request
    res = await self._client.request(
  File "/home/andres/coding/listapp2/venv/lib/python3.10/site-packages/httpx/_client.py", line 1533, in request
    return await self.send(request, auth=auth, follow_redirects=follow_redirects)
  File "/home/andres/coding/listapp2/venv/lib/python3.10/site-packages/httpx/_client.py", line 1620, in send
    response = await self._send_handling_auth(
  File "/home/andres/coding/listapp2/venv/lib/python3.10/site-packages/httpx/_client.py", line 1648, in _send_handling_auth
    response = await self._send_handling_redirects(
  File "/home/andres/coding/listapp2/venv/lib/python3.10/site-packages/httpx/_client.py", line 1685, in _send_handling_redirects
    response = await self._send_single_request(request)
  File "/home/andres/coding/listapp2/venv/lib/python3.10/site-packages/httpx/_client.py", line 1722, in _send_single_request
    response = await transport.handle_async_request(request)
  File "/home/andres/coding/listapp2/venv/lib/python3.10/site-packages/httpx/_transports/default.py", line 352, in handle_async_request
    with map_httpcore_exceptions():
  File "/usr/lib/python3.10/contextlib.py", line 153, in __exit__
    self.gen.throw(typ, value, traceback)
  File "/home/andres/coding/listapp2/venv/lib/python3.10/site-packages/httpx/_transports/default.py", line 77, in map_httpcore_exceptions
    raise mapped_exc(message) from exc
httpx.ReadTimeout

The above exception was the direct cause of the following exception:

Traceback (most recent call last):
  File "/home/andres/coding/listapp2/venv/lib/python3.10/site-packages/telegram/ext/_application.py", line 1104, in process_update
    await coroutine
  File "/home/andres/coding/listapp2/venv/lib/python3.10/site-packages/telegram/ext/_handler.py", line 141, in handle_update
    return await self.callback(update, context)
  File "/home/andres/coding/listapp2/TelegramBot/tlbot.py", line 46, in echo
    await context.bot.send_message(
  File "/home/andres/coding/listapp2/venv/lib/python3.10/site-packages/telegram/ext/_extbot.py", line 2598, in send_message
    return await super().send_message(
  File "/home/andres/coding/listapp2/venv/lib/python3.10/site-packages/telegram/_bot.py", line 331, in decorator
    result = await func(*args, **kwargs)  # skipcq: PYL-E1102
  File "/home/andres/coding/listapp2/venv/lib/python3.10/site-packages/telegram/_bot.py", line 760, in send_message
    return await self._send_message(
  File "/home/andres/coding/listapp2/venv/lib/python3.10/site-packages/telegram/ext/_extbot.py", line 488, in _send_message
    result = await super()._send_message(
  File "/home/andres/coding/listapp2/venv/lib/python3.10/site-packages/telegram/_bot.py", line 512, in _send_message
    result = await self._post(
  File "/home/andres/coding/listapp2/venv/lib/python3.10/site-packages/telegram/_bot.py", line 419, in _post
    return await self._do_post(
  File "/home/andres/coding/listapp2/venv/lib/python3.10/site-packages/telegram/ext/_extbot.py", line 306, in _do_post
    return await super()._do_post(
  File "/home/andres/coding/listapp2/venv/lib/python3.10/site-packages/telegram/_bot.py", line 450, in _do_post
    return await request.post(
  File "/home/andres/coding/listapp2/venv/lib/python3.10/site-packages/telegram/request/_baserequest.py", line 165, in post
    result = await self._request_wrapper(
  File "/home/andres/coding/listapp2/venv/lib/python3.10/site-packages/telegram/request/_baserequest.py", line 288, in _request_wrapper
    raise exc
  File "/home/andres/coding/listapp2/venv/lib/python3.10/site-packages/telegram/request/_baserequest.py", line 274, in _request_wrapper
    code, payload = await self.do_request(
  File "/home/andres/coding/listapp2/venv/lib/python3.10/site-packages/telegram/request/_httpxrequest.py", line 216, in do_request
    raise TimedOut from err
telegram.error.TimedOut: Timed out
TelegramBot 03-10 ERROR: No error handlers are registered, logging exception.
Traceback (most recent call last):
  File "/home/andres/coding/listapp2/venv/lib/python3.10/site-packages/telegram/ext/_application.py", line 1104, in process_update
    await coroutine
  File "/home/andres/coding/listapp2/venv/lib/python3.10/site-packages/telegram/ext/_handler.py", line 141, in handle_update
    return await self.callback(update, context)
  File "/home/andres/coding/listapp2/TelegramBot/tlbot.py", line 21, in echo
    user_entities = update.message.parse_entities(
AttributeError: 'NoneType' object has no attribute 'parse_entities'
TelegramBot 03-10 ERROR: No error handlers are registered, logging exception.
Traceback (most recent call last):
  File "/home/andres/coding/listapp2/venv/lib/python3.10/site-packages/telegram/ext/_application.py", line 1104, in process_update
    await coroutine
  File "/home/andres/coding/listapp2/venv/lib/python3.10/site-packages/telegram/ext/_handler.py", line 141, in handle_update
    return await self.callback(update, context)
  File "/home/andres/coding/listapp2/TelegramBot/tlbot.py", line 46, in echo
    await context.bot.send_message(
  File "/home/andres/coding/listapp2/venv/lib/python3.10/site-packages/telegram/ext/_extbot.py", line 2598, in send_message
    return await super().send_message(
  File "/home/andres/coding/listapp2/venv/lib/python3.10/site-packages/telegram/_bot.py", line 331, in decorator
    result = await func(*args, **kwargs)  # skipcq: PYL-E1102
  File "/home/andres/coding/listapp2/venv/lib/python3.10/site-packages/telegram/_bot.py", line 760, in send_message
    return await self._send_message(
  File "/home/andres/coding/listapp2/venv/lib/python3.10/site-packages/telegram/ext/_extbot.py", line 488, in _send_message
    result = await super()._send_message(
  File "/home/andres/coding/listapp2/venv/lib/python3.10/site-packages/telegram/_bot.py", line 512, in _send_message
    result = await self._post(
  File "/home/andres/coding/listapp2/venv/lib/python3.10/site-packages/telegram/_bot.py", line 419, in _post
    return await self._do_post(
  File "/home/andres/coding/listapp2/venv/lib/python3.10/site-packages/telegram/ext/_extbot.py", line 306, in _do_post
    return await super()._do_post(
  File "/home/andres/coding/listapp2/venv/lib/python3.10/site-packages/telegram/_bot.py", line 450, in _do_post
    return await request.post(
  File "/home/andres/coding/listapp2/venv/lib/python3.10/site-packages/telegram/request/_baserequest.py", line 165, in post
    result = await self._request_wrapper(
  File "/home/andres/coding/listapp2/venv/lib/python3.10/site-packages/telegram/request/_baserequest.py", line 314, in _request_wrapper
    raise RetryAfter(retry_after)
telegram.error.RetryAfter: Flood control exceeded. Retry in 39 seconds
TelegramBot 03-10 ERROR: No error handlers are registered, logging exception.
Traceback (most recent call last):
  File "/home/andres/coding/listapp2/venv/lib/python3.10/site-packages/telegram/ext/_application.py", line 1104, in process_update
    await coroutine
  File "/home/andres/coding/listapp2/venv/lib/python3.10/site-packages/telegram/ext/_handler.py", line 141, in handle_update
    return await self.callback(update, context)
  File "/home/andres/coding/listapp2/TelegramBot/tlbot.py", line 46, in echo
    await context.bot.send_message(
  File "/home/andres/coding/listapp2/venv/lib/python3.10/site-packages/telegram/ext/_extbot.py", line 2598, in send_message
    return await super().send_message(
  File "/home/andres/coding/listapp2/venv/lib/python3.10/site-packages/telegram/_bot.py", line 331, in decorator
    result = await func(*args, **kwargs)  # skipcq: PYL-E1102
  File "/home/andres/coding/listapp2/venv/lib/python3.10/site-packages/telegram/_bot.py", line 760, in send_message
    return await self._send_message(
  File "/home/andres/coding/listapp2/venv/lib/python3.10/site-packages/telegram/ext/_extbot.py", line 488, in _send_message
    result = await super()._send_message(
  File "/home/andres/coding/listapp2/venv/lib/python3.10/site-packages/telegram/_bot.py", line 512, in _send_message
    result = await self._post(
  File "/home/andres/coding/listapp2/venv/lib/python3.10/site-packages/telegram/_bot.py", line 419, in _post
    return await self._do_post(
  File "/home/andres/coding/listapp2/venv/lib/python3.10/site-packages/telegram/ext/_extbot.py", line 306, in _do_post
    return await super()._do_post(
  File "/home/andres/coding/listapp2/venv/lib/python3.10/site-packages/telegram/_bot.py", line 450, in _do_post
    return await request.post(
  File "/home/andres/coding/listapp2/venv/lib/python3.10/site-packages/telegram/request/_baserequest.py", line 165, in post
    result = await self._request_wrapper(
  File "/home/andres/coding/listapp2/venv/lib/python3.10/site-packages/telegram/request/_baserequest.py", line 314, in _request_wrapper
    raise RetryAfter(retry_after)
telegram.error.RetryAfter: Flood control exceeded. Retry in 39 seconds
TelegramBot 03-10 ERROR: No error handlers are registered, logging exception.
Traceback (most recent call last):
  File "/home/andres/coding/listapp2/venv/lib/python3.10/site-packages/telegram/ext/_application.py", line 1104, in process_update
    await coroutine
  File "/home/andres/coding/listapp2/venv/lib/python3.10/site-packages/telegram/ext/_handler.py", line 141, in handle_update
    return await self.callback(update, context)
  File "/home/andres/coding/listapp2/TelegramBot/tlbot.py", line 46, in echo
    await context.bot.send_message(
  File "/home/andres/coding/listapp2/venv/lib/python3.10/site-packages/telegram/ext/_extbot.py", line 2598, in send_message
    return await super().send_message(
  File "/home/andres/coding/listapp2/venv/lib/python3.10/site-packages/telegram/_bot.py", line 331, in decorator
    result = await func(*args, **kwargs)  # skipcq: PYL-E1102
  File "/home/andres/coding/listapp2/venv/lib/python3.10/site-packages/telegram/_bot.py", line 760, in send_message
    return await self._send_message(
  File "/home/andres/coding/listapp2/venv/lib/python3.10/site-packages/telegram/ext/_extbot.py", line 488, in _send_message
    result = await super()._send_message(
  File "/home/andres/coding/listapp2/venv/lib/python3.10/site-packages/telegram/_bot.py", line 512, in _send_message
    result = await self._post(
  File "/home/andres/coding/listapp2/venv/lib/python3.10/site-packages/telegram/_bot.py", line 419, in _post
    return await self._do_post(
  File "/home/andres/coding/listapp2/venv/lib/python3.10/site-packages/telegram/ext/_extbot.py", line 306, in _do_post
    return await super()._do_post(
  File "/home/andres/coding/listapp2/venv/lib/python3.10/site-packages/telegram/_bot.py", line 450, in _do_post
    return await request.post(
  File "/home/andres/coding/listapp2/venv/lib/python3.10/site-packages/telegram/request/_baserequest.py", line 165, in post
    result = await self._request_wrapper(
  File "/home/andres/coding/listapp2/venv/lib/python3.10/site-packages/telegram/request/_baserequest.py", line 314, in _request_wrapper
    raise RetryAfter(retry_after)
telegram.error.RetryAfter: Flood control exceeded. Retry in 39 seconds
TelegramBot 03-10 ERROR: No error handlers are registered, logging exception.
Traceback (most recent call last):
  File "/home/andres/coding/listapp2/venv/lib/python3.10/site-packages/telegram/ext/_application.py", line 1104, in process_update
    await coroutine
  File "/home/andres/coding/listapp2/venv/lib/python3.10/site-packages/telegram/ext/_handler.py", line 141, in handle_update
    return await self.callback(update, context)
  File "/home/andres/coding/listapp2/TelegramBot/tlbot.py", line 46, in echo
    await context.bot.send_message(
  File "/home/andres/coding/listapp2/venv/lib/python3.10/site-packages/telegram/ext/_extbot.py", line 2598, in send_message
    return await super().send_message(
  File "/home/andres/coding/listapp2/venv/lib/python3.10/site-packages/telegram/_bot.py", line 331, in decorator
    result = await func(*args, **kwargs)  # skipcq: PYL-E1102
  File "/home/andres/coding/listapp2/venv/lib/python3.10/site-packages/telegram/_bot.py", line 760, in send_message
    return await self._send_message(
  File "/home/andres/coding/listapp2/venv/lib/python3.10/site-packages/telegram/ext/_extbot.py", line 488, in _send_message
    result = await super()._send_message(
  File "/home/andres/coding/listapp2/venv/lib/python3.10/site-packages/telegram/_bot.py", line 512, in _send_message
    result = await self._post(
  File "/home/andres/coding/listapp2/venv/lib/python3.10/site-packages/telegram/_bot.py", line 419, in _post
    return await self._do_post(
  File "/home/andres/coding/listapp2/venv/lib/python3.10/site-packages/telegram/ext/_extbot.py", line 306, in _do_post
    return await super()._do_post(
  File "/home/andres/coding/listapp2/venv/lib/python3.10/site-packages/telegram/_bot.py", line 450, in _do_post
    return await request.post(
  File "/home/andres/coding/listapp2/venv/lib/python3.10/site-packages/telegram/request/_baserequest.py", line 165, in post
    result = await self._request_wrapper(
  File "/home/andres/coding/listapp2/venv/lib/python3.10/site-packages/telegram/request/_baserequest.py", line 314, in _request_wrapper
    raise RetryAfter(retry_after)
telegram.error.RetryAfter: Flood control exceeded. Retry in 38 seconds
TelegramBot 03-10 ERROR: No error handlers are registered, logging exception.
Traceback (most recent call last):
  File "/home/andres/coding/listapp2/venv/lib/python3.10/site-packages/telegram/ext/_application.py", line 1104, in process_update
    await coroutine
  File "/home/andres/coding/listapp2/venv/lib/python3.10/site-packages/telegram/ext/_handler.py", line 141, in handle_update
    return await self.callback(update, context)
  File "/home/andres/coding/listapp2/TelegramBot/tlbot.py", line 46, in echo
    await context.bot.send_message(
  File "/home/andres/coding/listapp2/venv/lib/python3.10/site-packages/telegram/ext/_extbot.py", line 2598, in send_message
    return await super().send_message(
  File "/home/andres/coding/listapp2/venv/lib/python3.10/site-packages/telegram/_bot.py", line 331, in decorator
    result = await func(*args, **kwargs)  # skipcq: PYL-E1102
  File "/home/andres/coding/listapp2/venv/lib/python3.10/site-packages/telegram/_bot.py", line 760, in send_message
    return await self._send_message(
  File "/home/andres/coding/listapp2/venv/lib/python3.10/site-packages/telegram/ext/_extbot.py", line 488, in _send_message
    result = await super()._send_message(
  File "/home/andres/coding/listapp2/venv/lib/python3.10/site-packages/telegram/_bot.py", line 512, in _send_message
    result = await self._post(
  File "/home/andres/coding/listapp2/venv/lib/python3.10/site-packages/telegram/_bot.py", line 419, in _post
    return await self._do_post(
  File "/home/andres/coding/listapp2/venv/lib/python3.10/site-packages/telegram/ext/_extbot.py", line 306, in _do_post
    return await super()._do_post(
  File "/home/andres/coding/listapp2/venv/lib/python3.10/site-packages/telegram/_bot.py", line 450, in _do_post
    return await request.post(
  File "/home/andres/coding/listapp2/venv/lib/python3.10/site-packages/telegram/request/_baserequest.py", line 165, in post
    result = await self._request_wrapper(
  File "/home/andres/coding/listapp2/venv/lib/python3.10/site-packages/telegram/request/_baserequest.py", line 314, in _request_wrapper
    raise RetryAfter(retry_after)
telegram.error.RetryAfter: Flood control exceeded. Retry in 38 seconds
TelegramBot 03-10 ERROR: No error handlers are registered, logging exception.
Traceback (most recent call last):
  File "/home/andres/coding/listapp2/venv/lib/python3.10/site-packages/telegram/ext/_application.py", line 1104, in process_update
    await coroutine
  File "/home/andres/coding/listapp2/venv/lib/python3.10/site-packages/telegram/ext/_handler.py", line 141, in handle_update
    return await self.callback(update, context)
  File "/home/andres/coding/listapp2/TelegramBot/tlbot.py", line 46, in echo
    await context.bot.send_message(
  File "/home/andres/coding/listapp2/venv/lib/python3.10/site-packages/telegram/ext/_extbot.py", line 2598, in send_message
    return await super().send_message(
  File "/home/andres/coding/listapp2/venv/lib/python3.10/site-packages/telegram/_bot.py", line 331, in decorator
    result = await func(*args, **kwargs)  # skipcq: PYL-E1102
  File "/home/andres/coding/listapp2/venv/lib/python3.10/site-packages/telegram/_bot.py", line 760, in send_message
    return await self._send_message(
  File "/home/andres/coding/listapp2/venv/lib/python3.10/site-packages/telegram/ext/_extbot.py", line 488, in _send_message
    result = await super()._send_message(
  File "/home/andres/coding/listapp2/venv/lib/python3.10/site-packages/telegram/_bot.py", line 512, in _send_message
    result = await self._post(
  File "/home/andres/coding/listapp2/venv/lib/python3.10/site-packages/telegram/_bot.py", line 419, in _post
    return await self._do_post(
  File "/home/andres/coding/listapp2/venv/lib/python3.10/site-packages/telegram/ext/_extbot.py", line 306, in _do_post
    return await super()._do_post(
  File "/home/andres/coding/listapp2/venv/lib/python3.10/site-packages/telegram/_bot.py", line 450, in _do_post
    return await request.post(
  File "/home/andres/coding/listapp2/venv/lib/python3.10/site-packages/telegram/request/_baserequest.py", line 165, in post
    result = await self._request_wrapper(
  File "/home/andres/coding/listapp2/venv/lib/python3.10/site-packages/telegram/request/_baserequest.py", line 314, in _request_wrapper
    raise RetryAfter(retry_after)
telegram.error.RetryAfter: Flood control exceeded. Retry in 38 seconds
TelegramBot 03-10 ERROR: No error handlers are registered, logging exception.
Traceback (most recent call last):
  File "/home/andres/coding/listapp2/venv/lib/python3.10/site-packages/telegram/ext/_application.py", line 1104, in process_update
    await coroutine
  File "/home/andres/coding/listapp2/venv/lib/python3.10/site-packages/telegram/ext/_handler.py", line 141, in handle_update
    return await self.callback(update, context)
  File "/home/andres/coding/listapp2/TelegramBot/tlbot.py", line 46, in echo
    await context.bot.send_message(
  File "/home/andres/coding/listapp2/venv/lib/python3.10/site-packages/telegram/ext/_extbot.py", line 2598, in send_message
    return await super().send_message(
  File "/home/andres/coding/listapp2/venv/lib/python3.10/site-packages/telegram/_bot.py", line 331, in decorator
    result = await func(*args, **kwargs)  # skipcq: PYL-E1102
  File "/home/andres/coding/listapp2/venv/lib/python3.10/site-packages/telegram/_bot.py", line 760, in send_message
    return await self._send_message(
  File "/home/andres/coding/listapp2/venv/lib/python3.10/site-packages/telegram/ext/_extbot.py", line 488, in _send_message
    result = await super()._send_message(
  File "/home/andres/coding/listapp2/venv/lib/python3.10/site-packages/telegram/_bot.py", line 512, in _send_message
    result = await self._post(
  File "/home/andres/coding/listapp2/venv/lib/python3.10/site-packages/telegram/_bot.py", line 419, in _post
    return await self._do_post(
  File "/home/andres/coding/listapp2/venv/lib/python3.10/site-packages/telegram/ext/_extbot.py", line 306, in _do_post
    return await super()._do_post(
  File "/home/andres/coding/listapp2/venv/lib/python3.10/site-packages/telegram/_bot.py", line 450, in _do_post
    return await request.post(
  File "/home/andres/coding/listapp2/venv/lib/python3.10/site-packages/telegram/request/_baserequest.py", line 165, in post
    result = await self._request_wrapper(
  File "/home/andres/coding/listapp2/venv/lib/python3.10/site-packages/telegram/request/_baserequest.py", line 314, in _request_wrapper
    raise RetryAfter(retry_after)
telegram.error.RetryAfter: Flood control exceeded. Retry in 37 seconds
TelegramBot 03-10 INFO: Application is stopping. This might take a moment.
TelegramBot 03-10 INFO: Application.stop() complete
TelegramBot 03-10 INFO: started TelegramBot
TelegramBot 03-10 INFO: Application started
TelegramBot 03-10 ERROR: No error handlers are registered, logging exception.
Traceback (most recent call last):
  File "/home/andres/coding/listapp2/venv/lib/python3.10/site-packages/telegram/ext/_application.py", line 1104, in process_update
    await coroutine
  File "/home/andres/coding/listapp2/venv/lib/python3.10/site-packages/telegram/ext/_handler.py", line 141, in handle_update
    return await self.callback(update, context)
  File "/home/andres/coding/listapp2/TelegramBot/tlbot.py", line 46, in echo
    text= bot_res
UnboundLocalError: local variable 'bot_res' referenced before assignment
TelegramBot 03-10 ERROR: No error handlers are registered, logging exception.
Traceback (most recent call last):
  File "/home/andres/coding/listapp2/venv/lib/python3.10/site-packages/telegram/ext/_application.py", line 1104, in process_update
    await coroutine
  File "/home/andres/coding/listapp2/venv/lib/python3.10/site-packages/telegram/ext/_handler.py", line 141, in handle_update
    return await self.callback(update, context)
  File "/home/andres/coding/listapp2/TelegramBot/tlbot.py", line 46, in echo
    text= bot_res
UnboundLocalError: local variable 'bot_res' referenced before assignment
TelegramBot 03-10 INFO: Received /start command
TelegramBot 03-10 INFO: Received /start command
TelegramBot 03-10 INFO: Application is stopping. This might take a moment.
TelegramBot 03-10 INFO: Application.stop() complete
TelegramBot 03-10 INFO: started TelegramBot
TelegramBot 03-10 INFO: Application started
TelegramBot 03-10 ERROR: No error handlers are registered, logging exception.
Traceback (most recent call last):
  File "/home/andres/coding/listapp2/venv/lib/python3.10/site-packages/telegram/ext/_application.py", line 1104, in process_update
    await coroutine
  File "/home/andres/coding/listapp2/venv/lib/python3.10/site-packages/telegram/ext/_handler.py", line 141, in handle_update
    return await self.callback(update, context)
  File "/home/andres/coding/listapp2/TelegramBot/tlbot.py", line 47, in echo
    text= bot_res
UnboundLocalError: local variable 'bot_res' referenced before assignment
TelegramBot 03-10 ERROR: No error handlers are registered, logging exception.
Traceback (most recent call last):
  File "/home/andres/coding/listapp2/venv/lib/python3.10/site-packages/telegram/ext/_application.py", line 1104, in process_update
    await coroutine
  File "/home/andres/coding/listapp2/venv/lib/python3.10/site-packages/telegram/ext/_handler.py", line 141, in handle_update
    return await self.callback(update, context)
  File "/home/andres/coding/listapp2/TelegramBot/tlbot.py", line 47, in echo
    )
UnboundLocalError: local variable 'bot_res' referenced before assignment
TelegramBot 03-10 INFO: Application is stopping. This might take a moment.
TelegramBot 03-10 INFO: Application.stop() complete
TelegramBot 03-10 INFO: started TelegramBot
TelegramBot 03-10 INFO: Application started
TelegramBot 03-10 ERROR: No error handlers are registered, logging exception.
Traceback (most recent call last):
  File "/home/andres/coding/listapp2/venv/lib/python3.10/site-packages/telegram/ext/_application.py", line 1104, in process_update
    await coroutine
  File "/home/andres/coding/listapp2/venv/lib/python3.10/site-packages/telegram/ext/_handler.py", line 141, in handle_update
    return await self.callback(update, context)
  File "/home/andres/coding/listapp2/TelegramBot/tlbot.py", line 46, in echo
    text= bot_res
UnboundLocalError: local variable 'bot_res' referenced before assignment
TelegramBot 03-10 ERROR: No error handlers are registered, logging exception.
Traceback (most recent call last):
  File "/home/andres/coding/listapp2/venv/lib/python3.10/site-packages/telegram/ext/_application.py", line 1104, in process_update
    await coroutine
  File "/home/andres/coding/listapp2/venv/lib/python3.10/site-packages/telegram/ext/_handler.py", line 141, in handle_update
    return await self.callback(update, context)
  File "/home/andres/coding/listapp2/TelegramBot/tlbot.py", line 46, in echo
    text= bot_res
UnboundLocalError: local variable 'bot_res' referenced before assignment
TelegramBot 03-10 ERROR: No error handlers are registered, logging exception.
Traceback (most recent call last):
  File "/home/andres/coding/listapp2/venv/lib/python3.10/site-packages/telegram/ext/_application.py", line 1104, in process_update
    await coroutine
  File "/home/andres/coding/listapp2/venv/lib/python3.10/site-packages/telegram/ext/_handler.py", line 141, in handle_update
    return await self.callback(update, context)
  File "/home/andres/coding/listapp2/TelegramBot/tlbot.py", line 46, in echo
    text= bot_res
UnboundLocalError: local variable 'bot_res' referenced before assignment
TelegramBot 03-10 ERROR: No error handlers are registered, logging exception.
Traceback (most recent call last):
  File "/home/andres/coding/listapp2/venv/lib/python3.10/site-packages/telegram/ext/_application.py", line 1104, in process_update
    await coroutine
  File "/home/andres/coding/listapp2/venv/lib/python3.10/site-packages/telegram/ext/_handler.py", line 141, in handle_update
    return await self.callback(update, context)
  File "/home/andres/coding/listapp2/TelegramBot/tlbot.py", line 46, in echo
    text= bot_res
UnboundLocalError: local variable 'bot_res' referenced before assignment
TelegramBot 03-10 ERROR: No error handlers are registered, logging exception.
Traceback (most recent call last):
  File "/home/andres/coding/listapp2/venv/lib/python3.10/site-packages/telegram/ext/_application.py", line 1104, in process_update
    await coroutine
  File "/home/andres/coding/listapp2/venv/lib/python3.10/site-packages/telegram/ext/_handler.py", line 141, in handle_update
    return await self.callback(update, context)
  File "/home/andres/coding/listapp2/TelegramBot/tlbot.py", line 46, in echo
    text= bot_res
UnboundLocalError: local variable 'bot_res' referenced before assignment
TelegramBot 03-10 INFO: Received /start command
TelegramBot 03-10 ERROR: No error handlers are registered, logging exception.
Traceback (most recent call last):
  File "/home/andres/coding/listapp2/venv/lib/python3.10/site-packages/telegram/ext/_application.py", line 1104, in process_update
    await coroutine
  File "/home/andres/coding/listapp2/venv/lib/python3.10/site-packages/telegram/ext/_handler.py", line 141, in handle_update
    return await self.callback(update, context)
  File "/home/andres/coding/listapp2/TelegramBot/tlbot.py", line 46, in echo
    text= bot_res
UnboundLocalError: local variable 'bot_res' referenced before assignment
TelegramBot 03-10 INFO: Application is stopping. This might take a moment.
TelegramBot 03-10 INFO: Application.stop() complete
TelegramBot 03-10 INFO: started TelegramBot
TelegramBot 03-10 INFO: started TelegramBot
TelegramBot 03-10 INFO: Application started
TelegramBot 03-10 INFO: Received /start command
TelegramBot 03-10 INFO: Application is stopping. This might take a moment.
TelegramBot 03-10 INFO: Application.stop() complete
TelegramBot 03-10 INFO: started TelegramBot
TelegramBot 03-10 INFO: Application started
TelegramBot 03-10 ERROR: No error handlers are registered, logging exception.
Traceback (most recent call last):
  File "/home/andres/coding/listapp2/venv/lib/python3.10/site-packages/telegram/ext/_application.py", line 1104, in process_update
    await coroutine
  File "/home/andres/coding/listapp2/venv/lib/python3.10/site-packages/telegram/ext/_handler.py", line 141, in handle_update
    return await self.callback(update, context)
  File "/home/andres/coding/listapp2/bot/tlbot.py", line 46, in echo
    text= bot_res
UnboundLocalError: local variable 'bot_res' referenced before assignment
TelegramBot 03-10 ERROR: No error handlers are registered, logging exception.
Traceback (most recent call last):
  File "/home/andres/coding/listapp2/venv/lib/python3.10/site-packages/telegram/ext/_application.py", line 1104, in process_update
    await coroutine
  File "/home/andres/coding/listapp2/venv/lib/python3.10/site-packages/telegram/ext/_handler.py", line 141, in handle_update
    return await self.callback(update, context)
  File "/home/andres/coding/listapp2/bot/tlbot.py", line 46, in echo
    text= bot_res
UnboundLocalError: local variable 'bot_res' referenced before assignment
TelegramBot 03-10 ERROR: No error handlers are registered, logging exception.
Traceback (most recent call last):
  File "/home/andres/coding/listapp2/venv/lib/python3.10/site-packages/telegram/ext/_application.py", line 1104, in process_update
    await coroutine
  File "/home/andres/coding/listapp2/venv/lib/python3.10/site-packages/telegram/ext/_handler.py", line 141, in handle_update
    return await self.callback(update, context)
  File "/home/andres/coding/listapp2/bot/tlbot.py", line 46, in echo
    text= bot_res
UnboundLocalError: local variable 'bot_res' referenced before assignment
TelegramBot 03-10 ERROR: No error handlers are registered, logging exception.
Traceback (most recent call last):
  File "/home/andres/coding/listapp2/venv/lib/python3.10/site-packages/telegram/ext/_application.py", line 1104, in process_update
    await coroutine
  File "/home/andres/coding/listapp2/venv/lib/python3.10/site-packages/telegram/ext/_handler.py", line 141, in handle_update
    return await self.callback(update, context)
  File "/home/andres/coding/listapp2/bot/tlbot.py", line 46, in echo
    text= bot_res
UnboundLocalError: local variable 'bot_res' referenced before assignment
TelegramBot 03-10 ERROR: No error handlers are registered, logging exception.
Traceback (most recent call last):
  File "/home/andres/coding/listapp2/venv/lib/python3.10/site-packages/telegram/ext/_application.py", line 1104, in process_update
    await coroutine
  File "/home/andres/coding/listapp2/venv/lib/python3.10/site-packages/telegram/ext/_handler.py", line 141, in handle_update
    return await self.callback(update, context)
  File "/home/andres/coding/listapp2/bot/tlbot.py", line 46, in echo
    text= bot_res
UnboundLocalError: local variable 'bot_res' referenced before assignment
TelegramBot 03-10 ERROR: No error handlers are registered, logging exception.
Traceback (most recent call last):
  File "/home/andres/coding/listapp2/venv/lib/python3.10/site-packages/telegram/ext/_application.py", line 1104, in process_update
    await coroutine
  File "/home/andres/coding/listapp2/venv/lib/python3.10/site-packages/telegram/ext/_handler.py", line 141, in handle_update
    return await self.callback(update, context)
  File "/home/andres/coding/listapp2/bot/tlbot.py", line 46, in echo
    text= bot_res
UnboundLocalError: local variable 'bot_res' referenced before assignment
TelegramBot 03-10 ERROR: No error handlers are registered, logging exception.
Traceback (most recent call last):
  File "/home/andres/coding/listapp2/venv/lib/python3.10/site-packages/telegram/ext/_application.py", line 1104, in process_update
    await coroutine
  File "/home/andres/coding/listapp2/venv/lib/python3.10/site-packages/telegram/ext/_handler.py", line 141, in handle_update
    return await self.callback(update, context)
  File "/home/andres/coding/listapp2/bot/tlbot.py", line 46, in echo
    text= bot_res
UnboundLocalError: local variable 'bot_res' referenced before assignment
TelegramBot 03-10 ERROR: No error handlers are registered, logging exception.
Traceback (most recent call last):
  File "/home/andres/coding/listapp2/venv/lib/python3.10/site-packages/telegram/ext/_application.py", line 1104, in process_update
    await coroutine
  File "/home/andres/coding/listapp2/venv/lib/python3.10/site-packages/telegram/ext/_handler.py", line 141, in handle_update
    return await self.callback(update, context)
  File "/home/andres/coding/listapp2/bot/tlbot.py", line 46, in echo
    text= bot_res
UnboundLocalError: local variable 'bot_res' referenced before assignment
TelegramBot 03-10 ERROR: No error handlers are registered, logging exception.
Traceback (most recent call last):
  File "/home/andres/coding/listapp2/venv/lib/python3.10/site-packages/telegram/ext/_application.py", line 1104, in process_update
    await coroutine
  File "/home/andres/coding/listapp2/venv/lib/python3.10/site-packages/telegram/ext/_handler.py", line 141, in handle_update
    return await self.callback(update, context)
  File "/home/andres/coding/listapp2/bot/tlbot.py", line 46, in echo
    text= bot_res
UnboundLocalError: local variable 'bot_res' referenced before assignment
TelegramBot 03-10 ERROR: No error handlers are registered, logging exception.
Traceback (most recent call last):
  File "/home/andres/coding/listapp2/venv/lib/python3.10/site-packages/telegram/ext/_application.py", line 1104, in process_update
    await coroutine
  File "/home/andres/coding/listapp2/venv/lib/python3.10/site-packages/telegram/ext/_handler.py", line 141, in handle_update
    return await self.callback(update, context)
  File "/home/andres/coding/listapp2/bot/tlbot.py", line 46, in echo
    text= bot_res
UnboundLocalError: local variable 'bot_res' referenced before assignment
TelegramBot 03-10 ERROR: No error handlers are registered, logging exception.
Traceback (most recent call last):
  File "/home/andres/coding/listapp2/venv/lib/python3.10/site-packages/telegram/ext/_application.py", line 1104, in process_update
    await coroutine
  File "/home/andres/coding/listapp2/venv/lib/python3.10/site-packages/telegram/ext/_handler.py", line 141, in handle_update
    return await self.callback(update, context)
  File "/home/andres/coding/listapp2/bot/tlbot.py", line 46, in echo
    text= bot_res
UnboundLocalError: local variable 'bot_res' referenced before assignment
TelegramBot 03-10 ERROR: No error handlers are registered, logging exception.
Traceback (most recent call last):
  File "/home/andres/coding/listapp2/venv/lib/python3.10/site-packages/telegram/ext/_application.py", line 1104, in process_update
    await coroutine
  File "/home/andres/coding/listapp2/venv/lib/python3.10/site-packages/telegram/ext/_handler.py", line 141, in handle_update
    return await self.callback(update, context)
  File "/home/andres/coding/listapp2/bot/tlbot.py", line 46, in echo
    text= bot_res
UnboundLocalError: local variable 'bot_res' referenced before assignment
TelegramBot 03-10 ERROR: No error handlers are registered, logging exception.
Traceback (most recent call last):
  File "/home/andres/coding/listapp2/venv/lib/python3.10/site-packages/telegram/ext/_application.py", line 1104, in process_update
    await coroutine
  File "/home/andres/coding/listapp2/venv/lib/python3.10/site-packages/telegram/ext/_handler.py", line 141, in handle_update
    return await self.callback(update, context)
  File "/home/andres/coding/listapp2/bot/tlbot.py", line 46, in echo
    text= bot_res
UnboundLocalError: local variable 'bot_res' referenced before assignment
TelegramBot 03-10 ERROR: No error handlers are registered, logging exception.
Traceback (most recent call last):
  File "/home/andres/coding/listapp2/venv/lib/python3.10/site-packages/telegram/ext/_application.py", line 1104, in process_update
    await coroutine
  File "/home/andres/coding/listapp2/venv/lib/python3.10/site-packages/telegram/ext/_handler.py", line 141, in handle_update
    return await self.callback(update, context)
  File "/home/andres/coding/listapp2/bot/tlbot.py", line 46, in echo
    text= bot_res
UnboundLocalError: local variable 'bot_res' referenced before assignment
TelegramBot 03-10 ERROR: No error handlers are registered, logging exception.
Traceback (most recent call last):
  File "/home/andres/coding/listapp2/venv/lib/python3.10/site-packages/telegram/ext/_application.py", line 1104, in process_update
    await coroutine
  File "/home/andres/coding/listapp2/venv/lib/python3.10/site-packages/telegram/ext/_handler.py", line 141, in handle_update
    return await self.callback(update, context)
  File "/home/andres/coding/listapp2/bot/tlbot.py", line 46, in echo
    text= bot_res
UnboundLocalError: local variable 'bot_res' referenced before assignment
TelegramBot 03-10 ERROR: No error handlers are registered, logging exception.
Traceback (most recent call last):
  File "/home/andres/coding/listapp2/venv/lib/python3.10/site-packages/telegram/ext/_application.py", line 1104, in process_update
    await coroutine
  File "/home/andres/coding/listapp2/venv/lib/python3.10/site-packages/telegram/ext/_handler.py", line 141, in handle_update
    return await self.callback(update, context)
  File "/home/andres/coding/listapp2/bot/tlbot.py", line 46, in echo
    text= bot_res
UnboundLocalError: local variable 'bot_res' referenced before assignment
TelegramBot 03-10 ERROR: No error handlers are registered, logging exception.
Traceback (most recent call last):
  File "/home/andres/coding/listapp2/venv/lib/python3.10/site-packages/telegram/ext/_application.py", line 1104, in process_update
    await coroutine
  File "/home/andres/coding/listapp2/venv/lib/python3.10/site-packages/telegram/ext/_handler.py", line 141, in handle_update
    return await self.callback(update, context)
  File "/home/andres/coding/listapp2/bot/tlbot.py", line 46, in echo
    text= bot_res
UnboundLocalError: local variable 'bot_res' referenced before assignment
TelegramBot 03-10 ERROR: No error handlers are registered, logging exception.
Traceback (most recent call last):
  File "/home/andres/coding/listapp2/venv/lib/python3.10/site-packages/telegram/ext/_application.py", line 1104, in process_update
    await coroutine
  File "/home/andres/coding/listapp2/venv/lib/python3.10/site-packages/telegram/ext/_handler.py", line 141, in handle_update
    return await self.callback(update, context)
  File "/home/andres/coding/listapp2/bot/tlbot.py", line 46, in echo
    text= bot_res
UnboundLocalError: local variable 'bot_res' referenced before assignment
TelegramBot 03-10 ERROR: No error handlers are registered, logging exception.
Traceback (most recent call last):
  File "/home/andres/coding/listapp2/venv/lib/python3.10/site-packages/telegram/ext/_application.py", line 1104, in process_update
    await coroutine
  File "/home/andres/coding/listapp2/venv/lib/python3.10/site-packages/telegram/ext/_handler.py", line 141, in handle_update
    return await self.callback(update, context)
  File "/home/andres/coding/listapp2/bot/tlbot.py", line 46, in echo
    text= bot_res
UnboundLocalError: local variable 'bot_res' referenced before assignment
TelegramBot 03-10 ERROR: No error handlers are registered, logging exception.
Traceback (most recent call last):
  File "/home/andres/coding/listapp2/venv/lib/python3.10/site-packages/telegram/ext/_application.py", line 1104, in process_update
    await coroutine
  File "/home/andres/coding/listapp2/venv/lib/python3.10/site-packages/telegram/ext/_handler.py", line 141, in handle_update
    return await self.callback(update, context)
  File "/home/andres/coding/listapp2/bot/tlbot.py", line 46, in echo
    text= bot_res
UnboundLocalError: local variable 'bot_res' referenced before assignment
TelegramBot 03-10 ERROR: No error handlers are registered, logging exception.
Traceback (most recent call last):
  File "/home/andres/coding/listapp2/venv/lib/python3.10/site-packages/telegram/ext/_application.py", line 1104, in process_update
    await coroutine
  File "/home/andres/coding/listapp2/venv/lib/python3.10/site-packages/telegram/ext/_handler.py", line 141, in handle_update
    return await self.callback(update, context)
  File "/home/andres/coding/listapp2/bot/tlbot.py", line 46, in echo
    text= bot_res
UnboundLocalError: local variable 'bot_res' referenced before assignment
TelegramBot 03-10 ERROR: No error handlers are registered, logging exception.
Traceback (most recent call last):
  File "/home/andres/coding/listapp2/venv/lib/python3.10/site-packages/telegram/ext/_application.py", line 1104, in process_update
    await coroutine
  File "/home/andres/coding/listapp2/venv/lib/python3.10/site-packages/telegram/ext/_handler.py", line 141, in handle_update
    return await self.callback(update, context)
  File "/home/andres/coding/listapp2/bot/tlbot.py", line 46, in echo
    text= bot_res
UnboundLocalError: local variable 'bot_res' referenced before assignment
TelegramBot 03-10 ERROR: No error handlers are registered, logging exception.
Traceback (most recent call last):
  File "/home/andres/coding/listapp2/venv/lib/python3.10/site-packages/telegram/ext/_application.py", line 1104, in process_update
    await coroutine
  File "/home/andres/coding/listapp2/venv/lib/python3.10/site-packages/telegram/ext/_handler.py", line 141, in handle_update
    return await self.callback(update, context)
  File "/home/andres/coding/listapp2/bot/tlbot.py", line 46, in echo
    text= bot_res
UnboundLocalError: local variable 'bot_res' referenced before assignment
TelegramBot 03-10 ERROR: No error handlers are registered, logging exception.
Traceback (most recent call last):
  File "/home/andres/coding/listapp2/venv/lib/python3.10/site-packages/telegram/ext/_application.py", line 1104, in process_update
    await coroutine
  File "/home/andres/coding/listapp2/venv/lib/python3.10/site-packages/telegram/ext/_handler.py", line 141, in handle_update
    return await self.callback(update, context)
  File "/home/andres/coding/listapp2/bot/tlbot.py", line 46, in echo
    text= bot_res
UnboundLocalError: local variable 'bot_res' referenced before assignment
TelegramBot 03-10 ERROR: No error handlers are registered, logging exception.
Traceback (most recent call last):
  File "/home/andres/coding/listapp2/venv/lib/python3.10/site-packages/telegram/ext/_application.py", line 1104, in process_update
    await coroutine
  File "/home/andres/coding/listapp2/venv/lib/python3.10/site-packages/telegram/ext/_handler.py", line 141, in handle_update
    return await self.callback(update, context)
  File "/home/andres/coding/listapp2/bot/tlbot.py", line 46, in echo
    text= bot_res
UnboundLocalError: local variable 'bot_res' referenced before assignment
TelegramBot 03-10 ERROR: No error handlers are registered, logging exception.
Traceback (most recent call last):
  File "/home/andres/coding/listapp2/venv/lib/python3.10/site-packages/telegram/ext/_application.py", line 1104, in process_update
    await coroutine
  File "/home/andres/coding/listapp2/venv/lib/python3.10/site-packages/telegram/ext/_handler.py", line 141, in handle_update
    return await self.callback(update, context)
  File "/home/andres/coding/listapp2/bot/tlbot.py", line 46, in echo
    text= bot_res
UnboundLocalError: local variable 'bot_res' referenced before assignment
TelegramBot 03-10 ERROR: No error handlers are registered, logging exception.
Traceback (most recent call last):
  File "/home/andres/coding/listapp2/venv/lib/python3.10/site-packages/telegram/ext/_application.py", line 1104, in process_update
    await coroutine
  File "/home/andres/coding/listapp2/venv/lib/python3.10/site-packages/telegram/ext/_handler.py", line 141, in handle_update
    return await self.callback(update, context)
  File "/home/andres/coding/listapp2/bot/tlbot.py", line 46, in echo
    text= bot_res
UnboundLocalError: local variable 'bot_res' referenced before assignment
TelegramBot 03-10 ERROR: No error handlers are registered, logging exception.
Traceback (most recent call last):
  File "/home/andres/coding/listapp2/venv/lib/python3.10/site-packages/telegram/ext/_application.py", line 1104, in process_update
    await coroutine
  File "/home/andres/coding/listapp2/venv/lib/python3.10/site-packages/telegram/ext/_handler.py", line 141, in handle_update
    return await self.callback(update, context)
  File "/home/andres/coding/listapp2/bot/tlbot.py", line 46, in echo
    text= bot_res
UnboundLocalError: local variable 'bot_res' referenced before assignment
TelegramBot 03-10 INFO: Received /start command
TelegramBot 03-10 ERROR: No error handlers are registered, logging exception.
Traceback (most recent call last):
  File "/home/andres/coding/listapp2/venv/lib/python3.10/site-packages/anyio/_core/_sockets.py", line 186, in connect_tcp
    addr_obj = ip_address(remote_host)
  File "/usr/lib/python3.10/ipaddress.py", line 54, in ip_address
    raise ValueError(f'{address!r} does not appear to be an IPv4 or IPv6 address')
ValueError: 'api.telegram.org' does not appear to be an IPv4 or IPv6 address

During handling of the above exception, another exception occurred:

Traceback (most recent call last):
  File "/home/andres/coding/listapp2/venv/lib/python3.10/site-packages/httpcore/backends/asyncio.py", line 111, in connect_tcp
    stream: anyio.abc.ByteStream = await anyio.connect_tcp(
  File "/home/andres/coding/listapp2/venv/lib/python3.10/site-packages/anyio/_core/_sockets.py", line 189, in connect_tcp
    gai_res = await getaddrinfo(
asyncio.exceptions.CancelledError

During handling of the above exception, another exception occurred:

Traceback (most recent call last):
  File "/home/andres/coding/listapp2/venv/lib/python3.10/site-packages/httpcore/_exceptions.py", line 10, in map_exceptions
    yield
  File "/home/andres/coding/listapp2/venv/lib/python3.10/site-packages/httpcore/backends/asyncio.py", line 110, in connect_tcp
    with anyio.fail_after(timeout):
  File "/home/andres/coding/listapp2/venv/lib/python3.10/site-packages/anyio/_core/_tasks.py", line 118, in __exit__
    raise TimeoutError
TimeoutError

During handling of the above exception, another exception occurred:

Traceback (most recent call last):
  File "/home/andres/coding/listapp2/venv/lib/python3.10/site-packages/httpx/_transports/default.py", line 60, in map_httpcore_exceptions
    yield
  File "/home/andres/coding/listapp2/venv/lib/python3.10/site-packages/httpx/_transports/default.py", line 353, in handle_async_request
    resp = await self._pool.handle_async_request(req)
  File "/home/andres/coding/listapp2/venv/lib/python3.10/site-packages/httpcore/_async/connection_pool.py", line 253, in handle_async_request
    raise exc
  File "/home/andres/coding/listapp2/venv/lib/python3.10/site-packages/httpcore/_async/connection_pool.py", line 237, in handle_async_request
    response = await connection.handle_async_request(request)
  File "/home/andres/coding/listapp2/venv/lib/python3.10/site-packages/httpcore/_async/connection.py", line 86, in handle_async_request
    raise exc
  File "/home/andres/coding/listapp2/venv/lib/python3.10/site-packages/httpcore/_async/connection.py", line 63, in handle_async_request
    stream = await self._connect(request)
  File "/home/andres/coding/listapp2/venv/lib/python3.10/site-packages/httpcore/_async/connection.py", line 111, in _connect
    stream = await self._network_backend.connect_tcp(**kwargs)
  File "/home/andres/coding/listapp2/venv/lib/python3.10/site-packages/httpcore/backends/auto.py", line 29, in connect_tcp
    return await self._backend.connect_tcp(
  File "/home/andres/coding/listapp2/venv/lib/python3.10/site-packages/httpcore/backends/asyncio.py", line 109, in connect_tcp
    with map_exceptions(exc_map):
  File "/usr/lib/python3.10/contextlib.py", line 153, in __exit__
    self.gen.throw(typ, value, traceback)
  File "/home/andres/coding/listapp2/venv/lib/python3.10/site-packages/httpcore/_exceptions.py", line 14, in map_exceptions
    raise to_exc(exc)
httpcore.ConnectTimeout

The above exception was the direct cause of the following exception:

Traceback (most recent call last):
  File "/home/andres/coding/listapp2/venv/lib/python3.10/site-packages/telegram/request/_httpxrequest.py", line 199, in do_request
    res = await self._client.request(
  File "/home/andres/coding/listapp2/venv/lib/python3.10/site-packages/httpx/_client.py", line 1533, in request
    return await self.send(request, auth=auth, follow_redirects=follow_redirects)
  File "/home/andres/coding/listapp2/venv/lib/python3.10/site-packages/httpx/_client.py", line 1620, in send
    response = await self._send_handling_auth(
  File "/home/andres/coding/listapp2/venv/lib/python3.10/site-packages/httpx/_client.py", line 1648, in _send_handling_auth
    response = await self._send_handling_redirects(
  File "/home/andres/coding/listapp2/venv/lib/python3.10/site-packages/httpx/_client.py", line 1685, in _send_handling_redirects
    response = await self._send_single_request(request)
  File "/home/andres/coding/listapp2/venv/lib/python3.10/site-packages/httpx/_client.py", line 1722, in _send_single_request
    response = await transport.handle_async_request(request)
  File "/home/andres/coding/listapp2/venv/lib/python3.10/site-packages/httpx/_transports/default.py", line 352, in handle_async_request
    with map_httpcore_exceptions():
  File "/usr/lib/python3.10/contextlib.py", line 153, in __exit__
    self.gen.throw(typ, value, traceback)
  File "/home/andres/coding/listapp2/venv/lib/python3.10/site-packages/httpx/_transports/default.py", line 77, in map_httpcore_exceptions
    raise mapped_exc(message) from exc
httpx.ConnectTimeout

The above exception was the direct cause of the following exception:

Traceback (most recent call last):
  File "/home/andres/coding/listapp2/venv/lib/python3.10/site-packages/telegram/ext/_application.py", line 1104, in process_update
    await coroutine
  File "/home/andres/coding/listapp2/venv/lib/python3.10/site-packages/telegram/ext/_handler.py", line 141, in handle_update
    return await self.callback(update, context)
  File "/home/andres/coding/listapp2/bot/tlbot.py", line 14, in start
    await context.bot.send_message(
  File "/home/andres/coding/listapp2/venv/lib/python3.10/site-packages/telegram/ext/_extbot.py", line 2598, in send_message
    return await super().send_message(
  File "/home/andres/coding/listapp2/venv/lib/python3.10/site-packages/telegram/_bot.py", line 331, in decorator
    result = await func(*args, **kwargs)  # skipcq: PYL-E1102
  File "/home/andres/coding/listapp2/venv/lib/python3.10/site-packages/telegram/_bot.py", line 760, in send_message
    return await self._send_message(
  File "/home/andres/coding/listapp2/venv/lib/python3.10/site-packages/telegram/ext/_extbot.py", line 488, in _send_message
    result = await super()._send_message(
  File "/home/andres/coding/listapp2/venv/lib/python3.10/site-packages/telegram/_bot.py", line 512, in _send_message
    result = await self._post(
  File "/home/andres/coding/listapp2/venv/lib/python3.10/site-packages/telegram/_bot.py", line 419, in _post
    return await self._do_post(
  File "/home/andres/coding/listapp2/venv/lib/python3.10/site-packages/telegram/ext/_extbot.py", line 306, in _do_post
    return await super()._do_post(
  File "/home/andres/coding/listapp2/venv/lib/python3.10/site-packages/telegram/_bot.py", line 450, in _do_post
    return await request.post(
  File "/home/andres/coding/listapp2/venv/lib/python3.10/site-packages/telegram/request/_baserequest.py", line 165, in post
    result = await self._request_wrapper(
  File "/home/andres/coding/listapp2/venv/lib/python3.10/site-packages/telegram/request/_baserequest.py", line 288, in _request_wrapper
    raise exc
  File "/home/andres/coding/listapp2/venv/lib/python3.10/site-packages/telegram/request/_baserequest.py", line 274, in _request_wrapper
    code, payload = await self.do_request(
  File "/home/andres/coding/listapp2/venv/lib/python3.10/site-packages/telegram/request/_httpxrequest.py", line 216, in do_request
    raise TimedOut from err
telegram.error.TimedOut: Timed out
TelegramBot 03-10 INFO: Received /start command
TelegramBot 03-10 INFO: Application is stopping. This might take a moment.
TelegramBot 03-10 INFO: Application.stop() complete
TelegramBot 03-10 INFO: started TelegramBot
TelegramBot 03-10 INFO: Application started
TelegramBot 03-10 INFO: Received /start command
TelegramBot 03-10 INFO: Application is stopping. This might take a moment.
TelegramBot 03-10 INFO: Application.stop() complete
